Workbook

Sheet 종합통계
A1: 개선 | B1: 부분개선 | C1: 변화없음 | D1: 불가 | E1: 불가(본류) | F1: 불가(조석) | G1: 총 지점수
A2: =COUNTIF(비교결과!$D$4:$D$67,종합통계!A1) -> 12 | B2: =COUNTIF(비교결과!$D$4:$D$67,종합통계!B1) -> 18 | C2: =COUNTIF(비교결과!$D$4:$D$67,종합통계!C1) -> 1 | D2: =COUNTIF(비교결과!$D$4:$D$67,종합통계!D1) -> 23 | E2: =COUNTIF(비교결과!$D$4:$D$67,종합통계!E1) -> 6 | F2: =COUNTIF(비교결과!$D$4:$D$67,종합통계!F1) -> 4 | G2: =SUM(A2:F2) -> 64

Sheet 비교결과
K1: Q Diff (%) | Z1: T Diff (min) | AD1: Q (cms)
E2: Q | G2: T | K2: 2023년 | S2: 2024년 | Z2: 2023년 | AB2: 2024년 | AD2: 보정전 | AF2: 보정후
A3: 유역 | B3: 하천 | C3: 지점 | D3: 종합판정 | E3: 2023 | F3: 2024 | G3: 2023 | H3: 2024 | I3: Peak_Obs(2023년) | J3: 보정전_Peak_Fore(2023년) | K3: 보정전_Peak_Diff(2023년) | L3: 보정후_Peak_Fore(2023년) | M3: 보정후_Peak_Diff(2023년) | N3: 보정전_Time_Diff(2023년) | O3: 보정후_Time_Diff(2023년) | P3: 개선여부(2023년) | Q3: Peak_Obs(2024년) | R3: 보정전_Peak_Fore(2024년) | S3: 보정전_Peak_Diff(2024년) | T3: 보정후_Peak_Fore(2024년) | U3: 보정후_Peak_Diff(2024년) | V3: 보정전_Time_Diff(2024년) | W3: 보정후_Time_Diff(2024년) | X3: 개선여부(2024년) | Y3: 상세내용 | Z3: 보정전 | AA3: 보정후 | AB3: 보정전 | AC3: 보정후 | AD3: 2023 | AE3: 2024 | AF3: 2023 | AG3: 2024 | AH3: Note
A4: 낙동강 | B4: 감천 | C4: 김천시(김천교) | D4: 부분개선 | E4: =IF(ABS(K4)>=ABS(M4),"O","X") -> X | F4: =IF(ABS(S4)>=ABS(U4),"O","X") -> O | G4: =IF(ABS(N4)>=ABS(O4),"O","X") -> O | H4: =IF(ABS(V4)>=ABS(W4),"O","X") -> O | I4: 383.57 | J4: 404.62 | K4: =ABS(J4-I4)/I4*100 -> 5.4879162 | L4: 233.24 | M4: =ABS(L4-I4)/I4*100 -> 39.192325 | N4: -90 | O4: -60 | P4: 부분개선 | Q4: 220.67 | R4: 489.41 | S4: =ABS(R4-Q4)/Q4*100 -> 121.78366 | T4: 241.07 | U4: =ABS(T4-Q4)/Q4*100 -> 9.2445733 | V4: -220 | W4: -160 | X4: 개선 | Y4: 한 연도 개선, 한 연도 부분개선 | Z4: =ABS(N4) -> 90 | AA4: =ABS(O4) -> 60 | AB4: =ABS(V4) -> 220 | AC4: =ABS(W4) -> 160 | AD4: =J4-I4 -> 21.05 | AE4: =R4-Q4 -> 268.74 | AF4: =L4-I4 -> -150.33 | AG4: =T4-Q4 -> 20.4
A5: 낙동강 | B5: 금천 | C5: 예천군(산양교) | D5: 개선 | E5: =IF(ABS(K5)>=ABS(M5),"O","X") -> O | F5: =IF(ABS(S5)>=ABS(U5),"O","X") -> X | G5: =IF(ABS(N5)>=ABS(O5),"O","X") -> O | H5: =IF(ABS(V5)>=ABS(W5),"O","X") -> O | I5: 748.17 | J5: 1158.72 | K5: =ABS(J5-I5)/I5*100 -> 54.873892 | L5: 1146.41 | M5: =ABS(L5-I5)/I5*100 -> 53.228544 | N5: -140 | O5: -110 | P5: 개선 | Q5: 102.08 | R5: 98.14 | S5: =ABS(R5-Q5)/Q5*100 -> 3.8597179 | T5: 97.84 | U5: =ABS(T5-Q5)/Q5*100 -> 4.153605 | V5: -70 | W5: -30 | X5: 부분개선 | Y5: 한 연도 개선, 한 연도 부분개선 | Z5: =ABS(N5) -> 140 | AA5: =ABS(O5) -> 110 | AB5: =ABS(V5) -> 70 | AC5: =ABS(W5) -> 30 | AD5: =J5-I5 -> 410.55 | AE5: =R5-Q5 -> -3.94 | AF5: =L5-I5 -> 398.24 | AG5: =T5-Q5 -> -4.24
A6: 낙동강 | B6: 금호강 | C6: 대구시(신암동) | D6: 불가 | E6: =IF(ABS(K6)>=ABS(M6),"O","X") -> X | F6: =IF(ABS(S6)>=ABS(U6),"O","X") -> O | G6: =IF(ABS(N6)>=ABS(O6),"O","X") -> O | H6: =IF(ABS(V6)>=ABS(W6),"O","X") -> X | I6: 1608.74 | J6: 1443.98 | K6: =ABS(J6-I6)/I6*100 -> 10.241556 | L6: 1197.42 | M6: =ABS(L6-I6)/I6*100 -> 25.567836 | N6: -280 | O6: -280 | P6: 불가 | Q6: 165.74 | R6: 897.09 | S6: =ABS(R6-Q6)/Q6*100 -> 441.26342 | T6: 655.52 | U6: =ABS(T6-Q6)/Q6*100 -> 295.51104 | V6: 210 | W6: 270 | X6: 부분개선 | Y6: 2023년: 불가, 2024년: 부분개선 | Z6: =ABS(N6) -> 280 | AA6: =ABS(O6) -> 280 | AB6: =ABS(V6) -> 210 | AC6: =ABS(W6) -> 270 | AD6: =J6-I6 -> -164.76 | AE6: =R6-Q6 -> 731.35 | AF6: =L6-I6 -> -411.32 | AG6: =T6-Q6 -> 489.78 | AH6: 이상치/결측치
A7: 낙동강 | B7: 금호강 | C7: 영천시(금창교) | D7: 불가 | E7: =IF(ABS(K7)>=ABS(M7),"O","X") -> X | F7: =IF(ABS(S7)>=ABS(U7),"O","X") -> X | G7: =IF(ABS(N7)>=ABS(O7),"O","X") -> X | H7: =IF(ABS(V7)>=ABS(W7),"O","X") -> X | I7: 1184.60 | J7: 923.23 | K7: =ABS(J7-I7)/I7*100 -> 22.063988 | L7: 826.52 | M7: =ABS(L7-I7)/I7*100 -> 30.227925 | N7: -40 | O7: -50 | P7: 불가 | Q7: 396.00 | R7: 387.57 | S7: =ABS(R7-Q7)/Q7*100 -> 2.1287879 | T7: 369.72 | U7: =ABS(T7-Q7)/Q7*100 -> 6.6363636 | V7: -580 | W7: -590 | X7: 불가 | Y7: 2023년: 불가, 2024년: 불가 | Z7: =ABS(N7) -> 40 | AA7: =ABS(O7) -> 50 | AB7: =ABS(V7) -> 580 | AC7: =ABS(W7) -> 590 | AD7: =J7-I7 -> -261.37 | AE7: =R7-Q7 -> -8.43 | AF7: =L7-I7 -> -358.08 | AG7: =T7-Q7 -> -26.28 | AH7: 수위-유량 곡선
A8: 낙동강 | B8: 금호강 | C8: 영천시(영동교) | D8: 불가 | E8: =IF(ABS(K8)>=ABS(M8),"O","X") -> X | F8: =IF(ABS(S8)>=ABS(U8),"O","X") -> O | G8: =IF(ABS(N8)>=ABS(O8),"O","X") -> O | H8: =IF(ABS(V8)>=ABS(W8),"O","X") -> O | I8: 603.69 | J8: 418.76 | K8: =ABS(J8-I8)/I8*100 -> 30.633272 | L8: 340.30 | M8: =ABS(L8-I8)/I8*100 -> 43.630009 | N8: 120 | O8: -50 | P8: 부분개선 | Q8: 8.89 | R8: 92.41 | S8: =ABS(R8-Q8)/Q8*100 -> 939.48256 | T8: 44.08 | U8: =ABS(T8-Q8)/Q8*100 -> 395.83802 | V8: 14570 | W8: 14140 | X8: 개선 | Y8: 한 연도 개선, 한 연도 부분개선 | Z8: =ABS(N8) -> 120 | AA8: =ABS(O8) -> 50 | AB8: =ABS(V8) -> 14570 | AC8: =ABS(W8) -> 14140 | AD8: =J8-I8 -> -184.93 | AE8: =R8-Q8 -> 83.52 | AF8: =L8-I8 -> -263.39 | AG8: =T8-Q8 -> 35.19 | AH8: 보운영
A9: 낙동강 | B9: 길안천 | C9: 안동시(묵계교) | D9: 개선 | E9: =IF(ABS(K9)>=ABS(M9),"O","X") -> O | F9: =IF(ABS(S9)>=ABS(U9),"O","X") -> O | G9: =IF(ABS(N9)>=ABS(O9),"O","X") -> O | H9: =IF(ABS(V9)>=ABS(W9),"O","X") -> O | I9: 732.24 | J9: 1061.86 | K9: =ABS(J9-I9)/I9*100 -> 45.015296 | L9: 734.45 | M9: =ABS(L9-I9)/I9*100 -> 0.30181361 | N9: -170 | O9: 60 | P9: 개선 | Q9: 595.05 | R9: 821.83 | S9: =ABS(R9-Q9)/Q9*100 -> 38.111083 | T9: 615.88 | U9: =ABS(T9-Q9)/Q9*100 -> 3.5005462 | V9: -80 | W9: -40 | X9: 개선 | Y9: 2023, 2024 모두 개선 | Z9: =ABS(N9) -> 170 | AA9: =ABS(O9) -> 60 | AB9: =ABS(V9) -> 80 | AC9: =ABS(W9) -> 40 | AD9: =J9-I9 -> 329.62 | AE9: =R9-Q9 -> 226.78 | AF9: =L9-I9 -> 2.21 | AG9: =T9-Q9 -> 20.83
A10: 낙동강 | B10: 낙동강 | C10: 대구시(성하리) | D10: 불가(본류) | E10: =IF(ABS(K10)>=ABS(M10),"O","X") -> O | F10: =IF(ABS(S10)>=ABS(U10),"O","X") -> O | G10: =IF(ABS(N10)>=ABS(O10),"O","X") -> X | H10: =IF(ABS(V10)>=ABS(W10),"O","X") -> O | I10: 8906.62 | J10: 11891.00 | K10: =ABS(J10-I10)/I10*100 -> 33.507436 | L10: 10729.75 | M10: =ABS(L10-I10)/I10*100 -> 20.469381 | N10: 3910 | O10: 3960 | P10: 부분개선 | Q10: 3767.40 | R10: 7779.58 | S10: =ABS(R10-Q10)/Q10*100 -> 106.49732 | T10: 6945.89 | U10: =ABS(T10-Q10)/Q10*100 -> 84.368265 | V10: -1120 | W10: -1110 | X10: 개선 | Y10: 조정제외(낙동강본류) | Z10: =ABS(N10) -> 3910 | AA10: =ABS(O10) -> 3960 | AB10: =ABS(V10) -> 1120 | AC10: =ABS(W10) -> 1110 | AD10: =J10-I10 -> 2984.38 | AE10: =R10-Q10 -> 4012.18 | AF10: =L10-I10 -> 1823.13 | AG10: =T10-Q10 -> 3178.49 | AH10: 본류(보운영)
A11: 낙동강 | B11: 낙동강 | C11: 밀양시(삼랑진교) | D11: 불가(본류) | E11: =IF(ABS(K11)>=ABS(M11),"O","X") -> O | F11: =IF(ABS(S11)>=ABS(U11),"O","X") -> O | G11: =IF(ABS(N11)>=ABS(O11),"O","X") -> O | H11: =IF(ABS(V11)>=ABS(W11),"O","X") -> O | I11: 8791.78 | J11: 19819.79 | K11: =ABS(J11-I11)/I11*100 -> 125.43546 | L11: 17073.09 | M11: =ABS(L11-I11)/I11*100 -> 94.193781 | N11: 2350 | O11: 2340 | P11: 개선 | Q11: 5976.70 | R11: 13951.47 | S11: =ABS(R11-Q11)/Q11*100 -> 133.43099 | T11: 11927.53 | U11: =ABS(T11-Q11)/Q11*100 -> 99.567152 | V11: -1100 | W11: -1090 | X11: 개선 | Y11: 조정제외(낙동강본류) | Z11: =ABS(N11) -> 2350 | AA11: =ABS(O11) -> 2340 | AB11: =ABS(V11) -> 1100 | AC11: =ABS(W11) -> 1090 | AD11: =J11-I11 -> 11028.01 | AE11: =R11-Q11 -> 7974.77 | AF11: =L11-I11 -> 8281.31 | AG11: =T11-Q11 -> 5950.83 | AH11: 본류(보운영)
A12: 낙동강 | B12: 낙동강 | C12: 봉화군(분천교) | D12: 부분개선 | E12: =IF(ABS(K12)>=ABS(M12),"O","X") -> O | F12: =IF(ABS(S12)>=ABS(U12),"O","X") -> O | G12: =IF(ABS(N12)>=ABS(O12),"O","X") -> O | H12: =IF(ABS(V12)>=ABS(W12),"O","X") -> O | I12: 953.21 | J12: 1541.97 | K12: =ABS(J12-I12)/I12*100 -> 61.766033 | L12: 1118.51 | M12: =ABS(L12-I12)/I12*100 -> 17.341404 | N12: -320 | O12: -290 | P12: 개선 | Q12: 448.13 | R12: 742.58 | S12: =ABS(R12-Q12)/Q12*100 -> 65.70638 | T12: 457.47 | U12: =ABS(T12-Q12)/Q12*100 -> 2.0842166 | V12: -250 | W12: -210 | X12: 개선 | Y12: 2023, 2024 모두 개선 | Z12: =ABS(N12) -> 320 | AA12: =ABS(O12) -> 290 | AB12: =ABS(V12) -> 250 | AC12: =ABS(W12) -> 210 | AD12: =J12-I12 -> 588.76 | AE12: =R12-Q12 -> 294.45 | AF12: =L12-I12 -> 165.3 | AG12: =T12-Q12 -> 9.34
A13: 낙동강 | B13: 낙동강 | C13: 부산시(구포대교) | D13: 불가(조석) | E13: =IF(ABS(K13)>=ABS(M13),"O","X") -> O | F13: =IF(ABS(S13)>=ABS(U13),"O","X") -> O | G13: =IF(ABS(N13)>=ABS(O13),"O","X") -> O | H13: =IF(ABS(V13)>=ABS(W13),"O","X") -> O | I13: 8684.15 | J13: 20731.42 | K13: =ABS(J13-I13)/I13*100 -> 138.72711 | L13: 17956.73 | M13: =ABS(L13-I13)/I13*100 -> 106.77591 | N13: 2780 | O13: 2770 | P13: 개선 | Q13: 7244.71 | R13: 15745.42 | S13: =ABS(R13-Q13)/Q13*100 -> 117.33679 | T13: 13715.59 | U13: =ABS(T13-Q13)/Q13*100 -> 89.318689 | V13: -940 | W13: -930 | X13: 개선 | Y13: 조정제외(조석영향) | Z13: =ABS(N13) -> 2780 | AA13: =ABS(O13) -> 2770 | AB13: =ABS(V13) -> 940 | AC13: =ABS(W13) -> 930 | AD13: =J13-I13 -> 12047.27 | AE13: =R13-Q13 -> 8500.71 | AF13: =L13-I13 -> 9272.58 | AG13: =T13-Q13 -> 6470.88 | AH13: 조석
A14: 낙동강 | B14: 낙동강 | C14: 예천군(구담교) | D14: 불가 | E14: =IF(ABS(K14)>=ABS(M14),"O","X") -> X | F14: =IF(ABS(S14)>=ABS(U14),"O","X") -> X | G14: =IF(ABS(N14)>=ABS(O14),"O","X") -> X | H14: =IF(ABS(V14)>=ABS(W14),"O","X") -> O | I14: 3471.54 | J14: 3019.53 | K14: =ABS(J14-I14)/I14*100 -> 13.020446 | L14: 2713.49 | M14: =ABS(L14-I14)/I14*100 -> 21.83613 | N14: 3560 | O14: 3580 | P14: 불가 | Q14: 1494.29 | R14: 1587.98 | S14: =ABS(R14-Q14)/Q14*100 -> 6.2698673 | T14: 1368.59 | U14: =ABS(T14-Q14)/Q14*100 -> 8.4120218 | V14: -740 | W14: -680 | X14: 부분개선 | Y14: 2023년: 불가, 2024년: 부분개선 | Z14: =ABS(N14) -> 3560 | AA14: =ABS(O14) -> 3580 | AB14: =ABS(V14) -> 740 | AC14: =ABS(W14) -> 680 | AD14: =J14-I14 -> -452.01 | AE14: =R14-Q14 -> 93.69 | AF14: =L14-I14 -> -758.05 | AG14: =T14-Q14 -> -125.7 | AH14: 수위-유량 곡선
A15: 낙동강 | B15: 낙동강 | C15: 예천군(상풍교) | D15: 불가 | E15: =IF(ABS(K15)>=ABS(M15),"O","X") -> O | F15: =IF(ABS(S15)>=ABS(U15),"O","X") -> O | G15: =IF(ABS(N15)>=ABS(O15),"O","X") -> O | H15: =IF(ABS(V15)>=ABS(W15),"O","X") -> O | I15: 7887.18 | J15: 8818.24 | K15: =ABS(J15-I15)/I15*100 -> 11.804726 | L15: 8125.72 | M15: =ABS(L15-I15)/I15*100 -> 3.0244016 | N15: -280 | O15: -270 | P15: 개선 | Q15: 2130.66 | R15: 3449.89 | S15: =ABS(R15-Q15)/Q15*100 -> 61.916495 | T15: 2939.62 | U15: =ABS(T15-Q15)/Q15*100 -> 37.967578 | V15: -920 | W15: -870 | X15: 개선 | Y15: 2023, 2024 모두 개선 | Z15: =ABS(N15) -> 280 | AA15: =ABS(O15) -> 270 | AB15: =ABS(V15) -> 920 | AC15: =ABS(W15) -> 870 | AD15: =J15-I15 -> 931.06 | AE15: =R15-Q15 -> 1319.23 | AF15: =L15-I15 -> 238.54 | AG15: =T15-Q15 -> 808.96 | AH15: 댐운영
A16: 낙동강 | B16: 낙동강 | C16: 의성군(낙단교) | D16: 불가(본류) | E16: =IF(ABS(K16)>=ABS(M16),"O","X") -> O | F16: =IF(ABS(S16)>=ABS(U16),"O","X") -> O | G16: =IF(ABS(N16)>=ABS(O16),"O","X") -> O | H16: =IF(ABS(V16)>=ABS(W16),"O","X") -> O | I16: 7836.36 | J16: 9613.39 | K16: =ABS(J16-I16)/I16*100 -> 22.676727 | L16: 8897.37 | M16: =ABS(L16-I16)/I16*100 -> 13.539577 | N16: -480 | O16: -460 | P16: 개선 | Q16: 3272.73 | R16: 5093.54 | S16: =ABS(R16-Q16)/Q16*100 -> 55.635815 | T16: 4473.67 | U16: =ABS(T16-Q16)/Q16*100 -> 36.695358 | V16: -1060 | W16: -1040 | X16: 개선 | Y16: 조정제외(낙동강본류) | Z16: =ABS(N16) -> 480 | AA16: =ABS(O16) -> 460 | AB16: =ABS(V16) -> 1060 | AC16: =ABS(W16) -> 1040 | AD16: =J16-I16 -> 1777.03 | AE16: =R16-Q16 -> 1820.81 | AF16: =L16-I16 -> 1061.01 | AG16: =T16-Q16 -> 1200.94 | AH16: 본류(보운영)
A17: 낙동강 | B17: 낙동강 | C17: 칠곡군(호국의다리) | D17: 불가(본류) | E17: =IF(ABS(K17)>=ABS(M17),"O","X") -> O | F17: =IF(ABS(S17)>=ABS(U17),"O","X") -> O | G17: =IF(ABS(N17)>=ABS(O17),"O","X") -> O | H17: =IF(ABS(V17)>=ABS(W17),"O","X") -> O | I17: 8154.59 | J17: 9881.17 | K17: =ABS(J17-I17)/I17*100 -> 21.173106 | L17: 9166.36 | M17: =ABS(L17-I17)/I17*100 -> 12.407368 | N17: -920 | O17: -910 | P17: 개선 | Q17: 2578.70 | R17: 6152.50 | S17: =ABS(R17-Q17)/Q17*100 -> 138.58921 | T17: 5473.97 | U17: =ABS(T17-Q17)/Q17*100 -> 112.27634 | V17: -260 | W17: -240 | X17: 개선 | Y17: 조정제외(낙동강본류) | Z17: =ABS(N17) -> 920 | AA17: =ABS(O17) -> 910 | AB17: =ABS(V17) -> 260 | AC17: =ABS(W17) -> 240 | AD17: =J17-I17 -> 1726.58 | AE17: =R17-Q17 -> 3573.8 | AF17: =L17-I17 -> 1011.77 | AG17: =T17-Q17 -> 2895.27 | AH17: 본류(보운영)
A18: 낙동강 | B18: 낙동강 | C18: 함안군(계내리) | D18: 불가(본류) | E18: =IF(ABS(K18)>=ABS(M18),"O","X") -> O | F18: =IF(ABS(S18)>=ABS(U18),"O","X") -> O | G18: =IF(ABS(N18)>=ABS(O18),"O","X") -> X | H18: =IF(ABS(V18)>=ABS(W18),"O","X") -> O | I18: 7401.19 | J18: 17401.06 | K18: =ABS(J18-I18)/I18*100 -> 135.11165 | L18: 15022.02 | M18: =ABS(L18-I18)/I18*100 -> 102.96763 | N18: 3200 | O18: 3220 | P18: 부분개선 | Q18: 5072.42 | R18: 11217.18 | S18: =ABS(R18-Q18)/Q18*100 -> 121.1406 | T18: 9500.16 | U18: =ABS(T18-Q18)/Q18*100 -> 87.290485 | V18: -1260 | W18: -1250 | X18: 개선 | Y18: 조정제외(낙동강본류) | Z18: =ABS(N18) -> 3200 | AA18: =ABS(O18) -> 3220 | AB18: =ABS(V18) -> 1260 | AC18: =ABS(W18) -> 1250 | AD18: =J18-I18 -> 9999.87 | AE18: =R18-Q18 -> 6144.76 | AF18: =L18-I18 -> 7620.83 | AG18: =T18-Q18 -> 4427.74 | AH18: 본류(보운영)
A19: 낙동강 | B19: 낙동강 | C19: 합천군(적포교) | D19: 불가(본류) | E19: =IF(ABS(K19)>=ABS(M19),"O","X") -> O | F19: =IF(ABS(S19)>=ABS(U19),"O","X") -> O | G19: =IF(ABS(N19)>=ABS(O19),"O","X") -> X | H19: =IF(ABS(V19)>=ABS(W19),"O","X") -> O | I19: 8244.56 | J19: 14999.14 | K19: =ABS(J19-I19)/I19*100 -> 81.92772 | L19: 12920.78 | M19: =ABS(L19-I19)/I19*100 -> 56.718855 | N19: 3610 | O19: 3620 | P19: 부분개선 | Q19: 4563.87 | R19: 8647.73 | S19: =ABS(R19-Q19)/Q19*100 -> 89.482391 | T19: 7615.15 | U19: =ABS(T19-Q19)/Q19*100 -> 66.857294 | V19: -1280 | W19: -1270 | X19: 개선 | Y19: 조정제외(낙동강본류) | Z19: =ABS(N19) -> 3610 | AA19: =ABS(O19) -> 3620 | AB19: =ABS(V19) -> 1280 | AC19: =ABS(W19) -> 1270 | AD19: =J19-I19 -> 6754.58 | AE19: =R19-Q19 -> 4083.86 | AF19: =L19-I19 -> 4676.22 | AG19: =T19-Q19 -> 3051.28 | AH19: 본류(보운영)
A20: 낙동강 | B20: 남강 | C20: 산청군(경호교) | D20: 불가 | E20: =IF(ABS(K20)>=ABS(M20),"O","X") -> X | F20: =IF(ABS(S20)>=ABS(U20),"O","X") -> X | G20: =IF(ABS(N20)>=ABS(O20),"O","X") -> O | H20: =IF(ABS(V20)>=ABS(W20),"O","X") -> O | I20: 2316.51 | J20: 2011.40 | K20: =ABS(J20-I20)/I20*100 -> 13.171107 | L20: 1949.99 | M20: =ABS(L20-I20)/I20*100 -> 15.822077 | N20: -150 | O20: -130 | P20: 부분개선 | Q20: 701.22 | R20: 737.60 | S20: =ABS(R20-Q20)/Q20*100 -> 5.1881007 | T20: 741.96 | U20: =ABS(T20-Q20)/Q20*100 -> 5.8098742 | V20: -400 | W20: -400 | X20: 불가 | Y20: 2023년: 부분개선, 2024년: 불가 | Z20: =ABS(N20) -> 150 | AA20: =ABS(O20) -> 130 | AB20: =ABS(V20) -> 400 | AC20: =ABS(W20) -> 400 | AD20: =J20-I20 -> -305.11 | AE20: =R20-Q20 -> 36.38 | AF20: =L20-I20 -> -366.52 | AG20: =T20-Q20 -> 40.74 | AH20: 수위-유량 곡선
A21: 낙동강 | B21: 남강 | C21: 의령군(정암교) | D21: 부분개선 | E21: =IF(ABS(K21)>=ABS(M21),"O","X") -> O | F21: =IF(ABS(S21)>=ABS(U21),"O","X") -> O | G21: =IF(ABS(N21)>=ABS(O21),"O","X") -> O | H21: =IF(ABS(V21)>=ABS(W21),"O","X") -> O | I21: 1337.33 | J21: 1907.98 | K21: =ABS(J21-I21)/I21*100 -> 42.670844 | L21: 1408.29 | M21: =ABS(L21-I21)/I21*100 -> 5.306095 | N21: -500 | O21: -500 | P21: 부분개선 | Q21: 1387.55 | R21: 2565.36 | S21: =ABS(R21-Q21)/Q21*100 -> 84.884148 | T21: 1713.74 | U21: =ABS(T21-Q21)/Q21*100 -> 23.508342 | V21: -430 | W21: -420 | X21: 개선 | Y21: 한 연도 개선, 한 연도 부분개선 | Z21: =ABS(N21) -> 500 | AA21: =ABS(O21) -> 500 | AB21: =ABS(V21) -> 430 | AC21: =ABS(W21) -> 420 | AD21: =J21-I21 -> 570.65 | AE21: =R21-Q21 -> 1177.81 | AF21: =L21-I21 -> 70.96 | AG21: =T21-Q21 -> 326.19
A22: 낙동강 | B22: 남강 | C22: 함양군(안의교) | D22: 불가 | E22: =IF(ABS(K22)>=ABS(M22),"O","X") -> O | F22: =IF(ABS(S22)>=ABS(U22),"O","X") -> #DIV/0! | G22: =IF(ABS(N22)>=ABS(O22),"O","X") -> O | H22: =IF(ABS(V22)>=ABS(W22),"O","X") -> O | I22: 45.44 | J22: 296.12 | K22: =ABS(J22-I22)/I22*100 -> 551.67254 | L22: 296.12 | M22: =ABS(L22-I22)/I22*100 -> 551.67254 | N22: 11690 | O22: 11690 | P22: 변화없음 | Q22: 0.00 | R22: 235.53 | S22: =ABS(R22-Q22)/Q22*100 -> #DIV/0! | T22: 235.53 | U22: =ABS(T22-Q22)/Q22*100 -> #DIV/0! | V22: 22400 | W22: 22400 | X22: 불가 | Y22: 2023년: 변화없음, 2024년: 불가 | Z22: =ABS(N22) -> 11690 | AA22: =ABS(O22) -> 11690 | AB22: =ABS(V22) -> 22400 | AC22: =ABS(W22) -> 22400 | AD22: =J22-I22 -> 250.68 | AE22: =R22-Q22 -> 235.53 | AF22: =L22-I22 -> 250.68 | AG22: =T22-Q22 -> 235.53 | AH22: 이상치/결측치
A23: 낙동강 | B23: 내성천 | C23: 봉화군(봉화대교) | D23: 불가 | E23: =IF(ABS(K23)>=ABS(M23),"O","X") -> X | F23: =IF(ABS(S23)>=ABS(U23),"O","X") -> O | G23: =IF(ABS(N23)>=ABS(O23),"O","X") -> O | H23: =IF(ABS(V23)>=ABS(W23),"O","X") -> O | I23: 851.51 | J23: 548.63 | K23: =ABS(J23-I23)/I23*100 -> 35.569753 | L23: 525.66 | M23: =ABS(L23-I23)/I23*100 -> 38.267313 | N23: -70 | O23: -70 | P23: 불가 | Q23: 60.08 | R23: 123.00 | S23: =ABS(R23-Q23)/Q23*100 -> 104.72703 | T23: 113.75 | U23: =ABS(T23-Q23)/Q23*100 -> 89.330892 | V23: -30 | W23: -20 | X23: 개선 | Y23: 2023년: 불가, 2024년: 개선 | Z23: =ABS(N23) -> 70 | AA23: =ABS(O23) -> 70 | AB23: =ABS(V23) -> 30 | AC23: =ABS(W23) -> 20 | AD23: =J23-I23 -> -302.88 | AE23: =R23-Q23 -> 62.92 | AF23: =L23-I23 -> -325.85 | AG23: =T23-Q23 -> 53.67 | AH23: 수위-유량 곡선
A24: 낙동강 | B24: 내성천 | C24: 예천군(회룡교) | D24: 부분개선 | E24: =IF(ABS(K24)>=ABS(M24),"O","X") -> O | F24: =IF(ABS(S24)>=ABS(U24),"O","X") -> O | G24: =IF(ABS(N24)>=ABS(O24),"O","X") -> O | H24: =IF(ABS(V24)>=ABS(W24),"O","X") -> O | I24: 3016.21 | J24: 3598.49 | K24: =ABS(J24-I24)/I24*100 -> 19.305022 | L24: 3015.01 | M24: =ABS(L24-I24)/I24*100 -> 0.039785028 | N24: -210 | O24: -190 | P24: 개선 | Q24: 388.09 | R24: 708.05 | S24: =ABS(R24-Q24)/Q24*100 -> 82.444794 | T24: 499.52 | U24: =ABS(T24-Q24)/Q24*100 -> 28.712412 | V24: -840 | W24: -560 | X24: 개선 | Y24: 2023, 2024 모두 개선 | Z24: =ABS(N24) -> 210 | AA24: =ABS(O24) -> 190 | AB24: =ABS(V24) -> 840 | AC24: =ABS(W24) -> 560 | AD24: =J24-I24 -> 582.28 | AE24: =R24-Q24 -> 319.96 | AF24: =L24-I24 -> -1.2 | AG24: =T24-Q24 -> 111.43
A25: 낙동강 | B25: 단장천 | C25: 밀양시(금곡리) | D25: 개선 | E25: =IF(ABS(K25)>=ABS(M25),"O","X") -> O | F25: =IF(ABS(S25)>=ABS(U25),"O","X") -> O | G25: =IF(ABS(N25)>=ABS(O25),"O","X") -> O | H25: =IF(ABS(V25)>=ABS(W25),"O","X") -> O | I25: 255.34 | J25: 535.41 | K25: =ABS(J25-I25)/I25*100 -> 109.68513 | L25: 214.44 | M25: =ABS(L25-I25)/I25*100 -> 16.017859 | N25: -2680 | O25: -60 | P25: 개선 | Q25: 200.12 | R25: 490.55 | S25: =ABS(R25-Q25)/Q25*100 -> 145.12792 | T25: 215.48 | U25: =ABS(T25-Q25)/Q25*100 -> 7.6753948 | V25: -150 | W25: -30 | X25: 개선 | Y25: 2023, 2024 모두 개선 | Z25: =ABS(N25) -> 2680 | AA25: =ABS(O25) -> 60 | AB25: =ABS(V25) -> 150 | AC25: =ABS(W25) -> 30 | AD25: =J25-I25 -> 280.07 | AE25: =R25-Q25 -> 290.43 | AF25: =L25-I25 -> -40.9 | AG25: =T25-Q25 -> 15.36
A26: 낙동강 | B26: 동창천 | C26: 청도군(매전교) | D26: 불가 | E26: =IF(ABS(K26)>=ABS(M26),"O","X") -> O | F26: =IF(ABS(S26)>=ABS(U26),"O","X") -> O | G26: =IF(ABS(N26)>=ABS(O26),"O","X") -> X | H26: =IF(ABS(V26)>=ABS(W26),"O","X") -> O | I26: 1309.23 | J26: 134.90 | K26: =ABS(J26-I26)/I26*100 -> 89.696234 | L26: 165.30 | M26: =ABS(L26-I26)/I26*100 -> 87.374258 | N26: -160 | O26: -170 | P26: 부분개선 | Q26: 1212.63 | R26: 106.27 | S26: =ABS(R26-Q26)/Q26*100 -> 91.236404 | T26: 117.72 | U26: =ABS(T26-Q26)/Q26*100 -> 90.292175 | V26: -160 | W26: -140 | X26: 개선 | Y26: 한 연도 개선, 한 연도 부분개선 | Z26: =ABS(N26) -> 160 | AA26: =ABS(O26) -> 170 | AB26: =ABS(V26) -> 160 | AC26: =ABS(W26) -> 140 | AD26: =J26-I26 -> -1174.33 | AE26: =R26-Q26 -> -1106.36 | AF26: =L26-I26 -> -1143.93 | AG26: =T26-Q26 -> -1094.91 | AH26: 모형
A27: 낙동강 | B27: 미천 | C27: 안동시(운산리) | D27: 부분개선 | E27: =IF(ABS(K27)>=ABS(M27),"O","X") -> X | F27: =IF(ABS(S27)>=ABS(U27),"O","X") -> O | G27: =IF(ABS(N27)>=ABS(O27),"O","X") -> X | H27: =IF(ABS(V27)>=ABS(W27),"O","X") -> X | I27: 654.42 | J27: 283.00 | K27: =ABS(J27-I27)/I27*100 -> 56.7556 | L27: 175.58 | M27: =ABS(L27-I27)/I27*100 -> 73.170135 | N27: -20 | O27: 80 | P27: 불가 | Q27: 209.48 | R27: 320.85 | S27: =ABS(R27-Q27)/Q27*100 -> 53.16498 | T27: 235.29 | U27: =ABS(T27-Q27)/Q27*100 -> 12.320985 | V27: 40 | W27: 80 | X27: 부분개선 | Y27: 2023년: 불가, 2024년: 부분개선 | Z27: =ABS(N27) -> 20 | AA27: =ABS(O27) -> 80 | AB27: =ABS(V27) -> 40 | AC27: =ABS(W27) -> 80 | AD27: =J27-I27 -> -371.42 | AE27: =R27-Q27 -> 111.37 | AF27: =L27-I27 -> -478.84 | AG27: =T27-Q27 -> 25.81
A28: 낙동강 | B28: 밀양강 | C28: 밀양시(용평동) | D28: 부분개선 | E28: =IF(ABS(K28)>=ABS(M28),"O","X") -> X | F28: =IF(ABS(S28)>=ABS(U28),"O","X") -> O | G28: =IF(ABS(N28)>=ABS(O28),"O","X") -> O | H28: =IF(ABS(V28)>=ABS(W28),"O","X") -> O | I28: 1202.80 | J28: 1386.87 | K28: =ABS(J28-I28)/I28*100 -> 15.303459 | L28: 937.54 | M28: =ABS(L28-I28)/I28*100 -> 22.053542 | N28: 140 | O28: 0 | P28: 부분개선 | Q28: 535.41 | R28: 1050.99 | S28: =ABS(R28-Q28)/Q28*100 -> 96.296296 | T28: 608.34 | U28: =ABS(T28-Q28)/Q28*100 -> 13.621337 | V28: -130 | W28: -50 | X28: 개선 | Y28: 한 연도 개선, 한 연도 부분개선 | Z28: =ABS(N28) -> 140 | AA28: =ABS(O28) -> 0 | AB28: =ABS(V28) -> 130 | AC28: =ABS(W28) -> 50 | AD28: =J28-I28 -> 184.07 | AE28: =R28-Q28 -> 515.58 | AF28: =L28-I28 -> -265.26 | AG28: =T28-Q28 -> 72.93
A29: 낙동강 | B29: 반변천 | C29: 영양군(청암교) | D29: 부분개선 | E29: =IF(ABS(K29)>=ABS(M29),"O","X") -> O | F29: =IF(ABS(S29)>=ABS(U29),"O","X") -> O | G29: =IF(ABS(N29)>=ABS(O29),"O","X") -> X | H29: =IF(ABS(V29)>=ABS(W29),"O","X") -> O | I29: 920.75 | J29: 1226.01 | K29: =ABS(J29-I29)/I29*100 -> 33.153408 | L29: 962.49 | M29: =ABS(L29-I29)/I29*100 -> 4.5332609 | N29: -30 | O29: 80 | P29: 부분개선 | Q29: 278.72 | R29: 348.12 | S29: =ABS(R29-Q29)/Q29*100 -> 24.899541 | T29: 294.48 | U29: =ABS(T29-Q29)/Q29*100 -> 5.6544202 | V29: -150 | W29: -30 | X29: 개선 | Y29: 한 연도 개선, 한 연도 부분개선 | Z29: =ABS(N29) -> 30 | AA29: =ABS(O29) -> 80 | AB29: =ABS(V29) -> 150 | AC29: =ABS(W29) -> 30 | AD29: =J29-I29 -> 305.26 | AE29: =R29-Q29 -> 69.4 | AF29: =L29-I29 -> 41.74 | AG29: =T29-Q29 -> 15.76
A30: 낙동강 | B30: 병성천 | C30: 상주시(화계교) | D30: 부분개선 | E30: =IF(ABS(K30)>=ABS(M30),"O","X") -> X | F30: =IF(ABS(S30)>=ABS(U30),"O","X") -> O | G30: =IF(ABS(N30)>=ABS(O30),"O","X") -> X | H30: =IF(ABS(V30)>=ABS(W30),"O","X") -> O | I30: 207.23 | J30: 166.95 | K30: =ABS(J30-I30)/I30*100 -> 19.43734 | L30: 146.44 | M30: =ABS(L30-I30)/I30*100 -> 29.334556 | N30: 50 | O30: 60 | P30: 불가 | Q30: 144.94 | R30: 176.52 | S30: =ABS(R30-Q30)/Q30*100 -> 21.788326 | T30: 159.09 | U30: =ABS(T30-Q30)/Q30*100 -> 9.7626604 | V30: 130 | W30: 130 | X30: 부분개선 | Y30: 2023년: 불가, 2024년: 부분개선 | Z30: =ABS(N30) -> 50 | AA30: =ABS(O30) -> 60 | AB30: =ABS(V30) -> 130 | AC30: =ABS(W30) -> 130 | AD30: =J30-I30 -> -40.28 | AE30: =R30-Q30 -> 31.58 | AF30: =L30-I30 -> -60.79 | AG30: =T30-Q30 -> 14.15
A31: 낙동강 | B31: 북천 | C31: 상주시(후천교) | D31: 개선 | E31: =IF(ABS(K31)>=ABS(M31),"O","X") -> O | F31: =IF(ABS(S31)>=ABS(U31),"O","X") -> O | G31: =IF(ABS(N31)>=ABS(O31),"O","X") -> O | H31: =IF(ABS(V31)>=ABS(W31),"O","X") -> O | I31: 350.67 | J31: 228.44 | K31: =ABS(J31-I31)/I31*100 -> 34.856133 | L31: 239.01 | M31: =ABS(L31-I31)/I31*100 -> 31.841903 | N31: 150 | O31: -50 | P31: 개선 | Q31: 167.93 | R31: 149.99 | S31: =ABS(R31-Q31)/Q31*100 -> 10.683023 | T31: 162.39 | U31: =ABS(T31-Q31)/Q31*100 -> 3.2989936 | V31: -10 | W31: -10 | X31: 부분개선 | Y31: 한 연도 개선, 한 연도 부분개선 | Z31: =ABS(N31) -> 150 | AA31: =ABS(O31) -> 50 | AB31: =ABS(V31) -> 10 | AC31: =ABS(W31) -> 10 | AD31: =J31-I31 -> -122.23 | AE31: =R31-Q31 -> -17.94 | AF31: =L31-I31 -> -111.66 | AG31: =T31-Q31 -> -5.54
A32: 낙동강 | B32: 서천 | C32: 영주시(월호교) | D32: 부분개선 | E32: =IF(ABS(K32)>=ABS(M32),"O","X") -> O | F32: =IF(ABS(S32)>=ABS(U32),"O","X") -> X | G32: =IF(ABS(N32)>=ABS(O32),"O","X") -> O | H32: =IF(ABS(V32)>=ABS(W32),"O","X") -> O | I32: 1201.89 | J32: 1393.41 | K32: =ABS(J32-I32)/I32*100 -> 15.934903 | L32: 1384.93 | M32: =ABS(L32-I32)/I32*100 -> 15.229347 | N32: -10 | O32: 0 | P32: 개선 | Q32: 327.89 | R32: 290.88 | S32: =ABS(R32-Q32)/Q32*100 -> 11.287322 | T32: 290.55 | U32: =ABS(T32-Q32)/Q32*100 -> 11.387965 | V32: -80 | W32: -70 | X32: 부분개선 | Y32: 한 연도 개선, 한 연도 부분개선 | Z32: =ABS(N32) -> 10 | AA32: =ABS(O32) -> 0 | AB32: =ABS(V32) -> 80 | AC32: =ABS(W32) -> 70 | AD32: =J32-I32 -> 191.52 | AE32: =R32-Q32 -> -37.01 | AF32: =L32-I32 -> 183.04 | AG32: =T32-Q32 -> -37.34
A33: 낙동강 | B33: 신천 | C33: 대구시(성북교) | D33: 불가 | E33: =IF(ABS(K33)>=ABS(M33),"O","X") -> O | F33: =IF(ABS(S33)>=ABS(U33),"O","X") -> O | G33: =IF(ABS(N33)>=ABS(O33),"O","X") -> O | H33: =IF(ABS(V33)>=ABS(W33),"O","X") -> O | I33: 349.28 | J33: 542.10 | K33: =ABS(J33-I33)/I33*100 -> 55.204993 | L33: 542.10 | M33: =ABS(L33-I33)/I33*100 -> 55.204993 | N33: -100 | O33: -100 | P33: 변화없음 | Q33: 181.13 | R33: 208.95 | S33: =ABS(R33-Q33)/Q33*100 -> 15.359134 | T33: 208.95 | U33: =ABS(T33-Q33)/Q33*100 -> 15.359134 | V33: 16380 | W33: 16380 | X33: 변화없음 | Y33: 2023, 2024 모두 변화없음 (매개변수 조정 불필요) | Z33: =ABS(N33) -> 100 | AA33: =ABS(O33) -> 100 | AB33: =ABS(V33) -> 16380 | AC33: =ABS(W33) -> 16380 | AD33: =J33-I33 -> 192.82 | AE33: =R33-Q33 -> 27.82 | AF33: =L33-I33 -> 192.82 | AG33: =T33-Q33 -> 27.82 | AH33: 이상치/결측치
A34: 낙동강 | B34: 쌍계천 | C34: 의성군(덕은교) | D34: 부분개선 | E34: =IF(ABS(K34)>=ABS(M34),"O","X") -> O | F34: =IF(ABS(S34)>=ABS(U34),"O","X") -> O | G34: =IF(ABS(N34)>=ABS(O34),"O","X") -> X | H34: =IF(ABS(V34)>=ABS(W34),"O","X") -> O | I34: 489.46 | J34: 319.63 | K34: =ABS(J34-I34)/I34*100 -> 34.697422 | L34: 431.81 | M34: =ABS(L34-I34)/I34*100 -> 11.778286 | N34: -40 | O34: -50 | P34: 부분개선 | Q34: 459.97 | R34: 233.58 | S34: =ABS(R34-Q34)/Q34*100 -> 49.218427 | T34: 382.30 | U34: =ABS(T34-Q34)/Q34*100 -> 16.885884 | V34: 260 | W34: -70 | X34: 개선 | Y34: 한 연도 개선, 한 연도 부분개선 | Z34: =ABS(N34) -> 40 | AA34: =ABS(O34) -> 50 | AB34: =ABS(V34) -> 260 | AC34: =ABS(W34) -> 70 | AD34: =J34-I34 -> -169.83 | AE34: =R34-Q34 -> -226.39 | AF34: =L34-I34 -> -57.65 | AG34: =T34-Q34 -> -77.67
A35: 낙동강 | B35: 안림천 | C35: 고령군(귀원교) | D35: 부분개선 | E35: =IF(ABS(K35)>=ABS(M35),"O","X") -> O | F35: =IF(ABS(S35)>=ABS(U35),"O","X") -> O | G35: =IF(ABS(N35)>=ABS(O35),"O","X") -> O | H35: =IF(ABS(V35)>=ABS(W35),"O","X") -> O | I35: 815.22 | J35: 915.66 | K35: =ABS(J35-I35)/I35*100 -> 12.320601 | L35: 722.89 | M35: =ABS(L35-I35)/I35*100 -> 11.325777 | N35: -20 | O35: -10 | P35: 개선 | Q35: 111.04 | R35: 161.50 | S35: =ABS(R35-Q35)/Q35*100 -> 45.443084 | T35: 137.84 | U35: =ABS(T35-Q35)/Q35*100 -> 24.135447 | V35: -180 | W35: -180 | X35: 부분개선 | Y35: 한 연도 개선, 한 연도 부분개선 | Z35: =ABS(N35) -> 20 | AA35: =ABS(O35) -> 10 | AB35: =ABS(V35) -> 180 | AC35: =ABS(W35) -> 180 | AD35: =J35-I35 -> 100.44 | AE35: =R35-Q35 -> 50.46 | AF35: =L35-I35 -> -92.33 | AG35: =T35-Q35 -> 26.8
A36: 낙동강 | B36: 양산천 | C36: 양산시(양산교) | D36: 개선 | E36: =IF(ABS(K36)>=ABS(M36),"O","X") -> O | F36: =IF(ABS(S36)>=ABS(U36),"O","X") -> O | G36: =IF(ABS(N36)>=ABS(O36),"O","X") -> O | H36: =IF(ABS(V36)>=ABS(W36),"O","X") -> O | I36: 341.66 | J36: 688.93 | K36: =ABS(J36-I36)/I36*100 -> 101.64198 | L36: 584.08 | M36: =ABS(L36-I36)/I36*100 -> 70.95358 | N36: -230 | O36: -220 | P36: 개선 | Q36: 642.99 | R36: 723.83 | S36: =ABS(R36-Q36)/Q36*100 -> 12.572513 | T36: 676.53 | U36: =ABS(T36-Q36)/Q36*100 -> 5.2162553 | V36: -60 | W36: -20 | X36: 개선 | Y36: 2023, 2024 모두 개선 | Z36: =ABS(N36) -> 230 | AA36: =ABS(O36) -> 220 | AB36: =ABS(V36) -> 60 | AC36: =ABS(W36) -> 20 | AD36: =J36-I36 -> 347.27 | AE36: =R36-Q36 -> 80.84 | AF36: =L36-I36 -> 242.42 | AG36: =T36-Q36 -> 33.54
A37: 낙동강 | B37: 영강 | C37: 문경시(김용리) | D37: 개선 | E37: =IF(ABS(K37)>=ABS(M37),"O","X") -> X | F37: =IF(ABS(S37)>=ABS(U37),"O","X") -> O | G37: =IF(ABS(N37)>=ABS(O37),"O","X") -> O | H37: =IF(ABS(V37)>=ABS(W37),"O","X") -> O | I37: 2349.37 | J37: 2378.18 | K37: =ABS(J37-I37)/I37*100 -> 1.2262862 | L37: 2386.92 | M37: =ABS(L37-I37)/I37*100 -> 1.5983008 | N37: -40 | O37: -40 | P37: 불가 | Q37: 632.82 | R37: 626.06 | S37: =ABS(R37-Q37)/Q37*100 -> 1.0682343 | T37: 630.59 | U37: =ABS(T37-Q37)/Q37*100 -> 0.35239089 | V37: -260 | W37: -250 | X37: 개선 | Y37: 2023년: 불가, 2024년: 개선 | Z37: =ABS(N37) -> 40 | AA37: =ABS(O37) -> 40 | AB37: =ABS(V37) -> 260 | AC37: =ABS(W37) -> 250 | AD37: =J37-I37 -> 28.81 | AE37: =R37-Q37 -> -6.76 | AF37: =L37-I37 -> 37.55 | AG37: =T37-Q37 -> -2.23
A38: 낙동강 | B38: 영천강 | C38: 진주시(옥산교) | D38: 개선 | E38: =IF(ABS(K38)>=ABS(M38),"O","X") -> O | F38: =IF(ABS(S38)>=ABS(U38),"O","X") -> O | G38: =IF(ABS(N38)>=ABS(O38),"O","X") -> X | H38: =IF(ABS(V38)>=ABS(W38),"O","X") -> X | I38: 506.66 | J38: 390.44 | K38: =ABS(J38-I38)/I38*100 -> 22.93846 | L38: 570.49 | M38: =ABS(L38-I38)/I38*100 -> 12.598192 | N38: -30 | O38: -40 | P38: 부분개선 | Q38: 1032.16 | R38: 735.76 | S38: =ABS(R38-Q38)/Q38*100 -> 28.716478 | T38: 927.94 | U38: =ABS(T38-Q38)/Q38*100 -> 10.097272 | V38: -30 | W38: -40 | X38: 부분개선 | Y38: 2023, 2024 모두 부분개선 | Z38: =ABS(N38) -> 30 | AA38: =ABS(O38) -> 40 | AB38: =ABS(V38) -> 30 | AC38: =ABS(W38) -> 40 | AD38: =J38-I38 -> -116.22 | AE38: =R38-Q38 -> -296.4 | AF38: =L38-I38 -> 63.83 | AG38: =T38-Q38 -> -104.22
A39: 낙동강 | B39: 오목천 | C39: 경산시(압량교) | D39: 개선 | E39: =IF(ABS(K39)>=ABS(M39),"O","X") -> O | F39: =IF(ABS(S39)>=ABS(U39),"O","X") -> O | G39: =IF(ABS(N39)>=ABS(O39),"O","X") -> O | H39: =IF(ABS(V39)>=ABS(W39),"O","X") -> O | I39: 253.49 | J39: 147.57 | K39: =ABS(J39-I39)/I39*100 -> 41.784686 | L39: 147.65 | M39: =ABS(L39-I39)/I39*100 -> 41.753126 | N39: -40 | O39: 0 | P39: 개선 | Q39: 89.89 | R39: 89.71 | S39: =ABS(R39-Q39)/Q39*100 -> 0.20024474 | T39: 89.75 | U39: =ABS(T39-Q39)/Q39*100 -> 0.15574591 | V39: -50 | W39: -20 | X39: 개선 | Y39: 2023, 2024 모두 개선 | Z39: =ABS(N39) -> 40 | AA39: =ABS(O39) -> 0 | AB39: =ABS(V39) -> 50 | AC39: =ABS(W39) -> 20 | AD39: =J39-I39 -> -105.92 | AE39: =R39-Q39 -> -0.18 | AF39: =L39-I39 -> -105.84 | AG39: =T39-Q39 -> -0.14
A40: 낙동강 | B40: 위천 | C40: 군위군(무성리) | D40: 변화없음 | E40: =IF(ABS(K40)>=ABS(M40),"O","X") -> O | F40: =IF(ABS(S40)>=ABS(U40),"O","X") -> O | G40: =IF(ABS(N40)>=ABS(O40),"O","X") -> O | H40: =IF(ABS(V40)>=ABS(W40),"O","X") -> O | I40: 696.22 | J40: 768.04 | K40: =ABS(J40-I40)/I40*100 -> 10.315705 | L40: 768.04 | M40: =ABS(L40-I40)/I40*100 -> 10.315705 | N40: -30 | O40: -30 | P40: 변화없음 | Q40: 517.78 | R40: 484.57 | S40: =ABS(R40-Q40)/Q40*100 -> 6.413921 | T40: 484.57 | U40: =ABS(T40-Q40)/Q40*100 -> 6.413921 | V40: 280 | W40: 280 | X40: 변화없음 | Y40: 2023, 2024 모두 변화없음 (매개변수 조정 불필요) | Z40: =ABS(N40) -> 30 | AA40: =ABS(O40) -> 30 | AB40: =ABS(V40) -> 280 | AC40: =ABS(W40) -> 280 | AD40: =J40-I40 -> 71.82 | AE40: =R40-Q40 -> -33.21 | AF40: =L40-I40 -> 71.82 | AG40: =T40-Q40 -> -33.21
...

Sheet 상세_비교결과
H1: 2023년 | P1: 2024년
A2: 유역 | B2: 하천 | C2: 지점 | D2: 종합판정 | E2: Note | F2: Peak_Obs(2023년) | G2: 보정전_Peak_Fore(2023년) | H2: 보정전_Peak_Diff(2023년) | I2: 보정후_Peak_Fore(2023년) | J2: 보정후_Peak_Diff(2023년) | K2: 보정전_Time_Diff(2023년) | L2: 보정후_Time_Diff(2023년) | M2: 개선여부(2023년) | N2: Peak_Obs(2024년) | O2: 보정전_Peak_Fore(2024년) | P2: 보정전_Peak_Diff(2024년) | Q2: 보정후_Peak_Fore(2024년) | R2: 보정후_Peak_Diff(2024년) | S2: 보정전_Time_Diff(2024년) | T2: 보정후_Time_Diff(2024년) | U2: 개선여부(2024년) | V2: 상세내용
A3: 낙동강 | B3: 감천 | C3: 김천시(김천교) | D3: 부분개선 | F3: 383.57 | G3: 404.62 | H3: 5.49 | I3: 233.24 | J3: -39.19 | K3: -90 | L3: -60 | M3: 부분개선 | N3: 220.67 | O3: 489.41 | P3: 121.78 | Q3: 241.07 | R3: 9.24 | S3: -220 | T3: -160 | U3: 개선 | V3: 한 연도 개선, 한 연도 부분개선
A4: 낙동강 | B4: 금천 | C4: 예천군(산양교) | D4: 개선 | F4: 748.17 | G4: 1158.72 | H4: 54.87 | I4: 1146.41 | J4: 53.23 | K4: -140 | L4: -110 | M4: 개선 | N4: 102.08 | O4: 98.14 | P4: -3.86 | Q4: 97.84 | R4: -4.15 | S4: -70 | T4: -30 | U4: 부분개선 | V4: 한 연도 개선, 한 연도 부분개선
A5: 낙동강 | B5: 금호강 | C5: 대구시(신암동) | D5: 불가 | E5: 이상치/결측치 | F5: 1608.74 | G5: 1443.98 | H5: -10.24 | I5: 1197.42 | J5: -25.57 | K5: -280 | L5: -280 | M5: 불가 | N5: 165.74 | O5: 897.09 | P5: 441.26 | Q5: 655.52 | R5: 295.51 | S5: 210 | T5: 270 | U5: 부분개선 | V5: 2023년: 불가, 2024년: 부분개선
A6: 낙동강 | B6: 금호강 | C6: 영천시(금창교) | D6: 불가 | E6: 수위-유량 곡선 | F6: 1184.60 | G6: 923.23 | H6: -22.06 | I6: 826.52 | J6: -30.23 | K6: -40 | L6: -50 | M6: 불가 | N6: 396.00 | O6: 387.57 | P6: -2.13 | Q6: 369.72 | R6: -6.64 | S6: -580 | T6: -590 | U6: 불가 | V6: 2023년: 불가, 2024년: 불가
A7: 낙동강 | B7: 금호강 | C7: 영천시(영동교) | D7: 불가 | E7: 보운영 | F7: 603.69 | G7: 418.76 | H7: -30.63 | I7: 340.30 | J7: -43.63 | K7: 120 | L7: -50 | M7: 부분개선 | N7: 8.89 | O7: 92.41 | P7: 939.48 | Q7: 44.08 | R7: 395.84 | S7: 14570 | T7: 14140 | U7: 개선 | V7: 한 연도 개선, 한 연도 부분개선
A8: 낙동강 | B8: 길안천 | C8: 안동시(묵계교) | D8: 개선 | F8: 732.24 | G8: 1061.86 | H8: 45.02 | I8: 734.45 | J8: 0.30 | K8: -170 | L8: 60 | M8: 개선 | N8: 595.05 | O8: 821.83 | P8: 38.11 | Q8: 615.88 | R8: 3.50 | S8: -80 | T8: -40 | U8: 개선 | V8: 2023, 2024 모두 개선
A9: 낙동강 | B9: 낙동강 | C9: 대구시(성하리) | D9: 불가 | E9: 본류(보운영) | F9: 8906.62 | G9: 11891.00 | H9: 33.51 | I9: 10729.75 | J9: 20.47 | K9: 3910 | L9: 3960 | M9: 부분개선 | N9: 3767.40 | O9: 7779.58 | P9: 106.50 | Q9: 6945.89 | R9: 84.37 | S9: -1120 | T9: -1110 | U9: 개선 | V9: 조정제외(낙동강본류)
A10: 낙동강 | B10: 낙동강 | C10: 밀양시(삼랑진교) | D10: 불가 | E10: 본류(보운영) | F10: 8791.78 | G10: 19819.79 | H10: 125.44 | I10: 17073.09 | J10: 94.19 | K10: 2350 | L10: 2340 | M10: 개선 | N10: 5976.70 | O10: 13951.47 | P10: 133.43 | Q10: 11927.53 | R10: 99.57 | S10: -1100 | T10: -1090 | U10: 개선 | V10: 조정제외(낙동강본류)
A11: 낙동강 | B11: 낙동강 | C11: 봉화군(분천교) | D11: 개선 | F11: 953.21 | G11: 1541.97 | H11: 61.77 | I11: 1118.51 | J11: 17.34 | K11: -320 | L11: -290 | M11: 개선 | N11: 448.13 | O11: 742.58 | P11: 65.71 | Q11: 457.47 | R11: 2.08 | S11: -250 | T11: -210 | U11: 개선 | V11: 2023, 2024 모두 개선
A12: 낙동강 | B12: 낙동강 | C12: 부산시(구포대교) | D12: 불가 | E12: 조석 | F12: 8684.15 | G12: 20731.42 | H12: 138.73 | I12: 17956.73 | J12: 106.78 | K12: 2780 | L12: 2770 | M12: 개선 | N12: 7244.71 | O12: 15745.42 | P12: 117.34 | Q12: 13715.59 | R12: 89.32 | S12: -940 | T12: -930 | U12: 개선 | V12: 조정제외(조석영향)
A13: 낙동강 | B13: 낙동강 | C13: 예천군(구담교) | D13: 불가 | E13: 수위-유량 곡선 | F13: 3471.54 | G13: 3019.53 | H13: -13.02 | I13: 2713.49 | J13: -21.84 | K13: 3560 | L13: 3580 | M13: 불가 | N13: 1494.29 | O13: 1587.98 | P13: 6.27 | Q13: 1368.59 | R13: -8.41 | S13: -740 | T13: -680 | U13: 부분개선 | V13: 2023년: 불가, 2024년: 부분개선
A14: 낙동강 | B14: 낙동강 | C14: 예천군(상풍교) | D14: 불가 | E14: 댐운영 | F14: 7887.18 | G14: 8818.24 | H14: 11.80 | I14: 8125.72 | J14: 3.02 | K14: -280 | L14: -270 | M14: 개선 | N14: 2130.66 | O14: 3449.89 | P14: 61.92 | Q14: 2939.62 | R14: 37.97 | S14: -920 | T14: -870 | U14: 개선 | V14: 2023, 2024 모두 개선
A15: 낙동강 | B15: 낙동강 | C15: 의성군(낙단교) | D15: 불가 | E15: 본류(보운영) | F15: 7836.36 | G15: 9613.39 | H15: 22.68 | I15: 8897.37 | J15: 13.54 | K15: -480 | L15: -460 | M15: 개선 | N15: 3272.73 | O15: 5093.54 | P15: 55.64 | Q15: 4473.67 | R15: 36.70 | S15: -1060 | T15: -1040 | U15: 개선 | V15: 조정제외(낙동강본류)
A16: 낙동강 | B16: 낙동강 | C16: 칠곡군(호국의다리) | D16: 불가 | E16: 본류(보운영) | F16: 8154.59 | G16: 9881.17 | H16: 21.17 | I16: 9166.36 | J16: 12.41 | K16: -920 | L16: -910 | M16: 개선 | N16: 2578.70 | O16: 6152.50 | P16: 138.59 | Q16: 5473.97 | R16: 112.28 | S16: -260 | T16: -240 | U16: 개선 | V16: 조정제외(낙동강본류)
A17: 낙동강 | B17: 낙동강 | C17: 함안군(계내리) | D17: 불가 | E17: 본류(보운영) | F17: 7401.19 | G17: 17401.06 | H17: 135.11 | I17: 15022.02 | J17: 102.97 | K17: 3200 | L17: 3220 | M17: 부분개선 | N17: 5072.42 | O17: 11217.18 | P17: 121.14 | Q17: 9500.16 | R17: 87.29 | S17: -1260 | T17: -1250 | U17: 개선 | V17: 조정제외(낙동강본류)
A18: 낙동강 | B18: 낙동강 | C18: 합천군(적포교) | D18: 불가 | E18: 본류(보운영) | F18: 8244.56 | G18: 14999.14 | H18: 81.93 | I18: 12920.78 | J18: 56.72 | K18: 3610 | L18: 3620 | M18: 부분개선 | N18: 4563.87 | O18: 8647.73 | P18: 89.48 | Q18: 7615.15 | R18: 66.86 | S18: -1280 | T18: -1270 | U18: 개선 | V18: 조정제외(낙동강본류)
A19: 낙동강 | B19: 남강 | C19: 산청군(경호교) | D19: 불가 | E19: 수위-유량 곡선 | F19: 2316.51 | G19: 2011.40 | H19: -13.17 | I19: 1949.99 | J19: -15.82 | K19: -150 | L19: -130 | M19: 부분개선 | N19: 701.22 | O19: 737.60 | P19: 5.19 | Q19: 741.96 | R19: 5.81 | S19: -400 | T19: -400 | U19: 불가 | V19: 2023년: 부분개선, 2024년: 불가
A20: 낙동강 | B20: 남강 | C20: 의령군(정암교) | D20: 개선 | F20: 1337.33 | G20: 1907.98 | H20: 42.67 | I20: 1408.29 | J20: 5.31 | K20: -500 | L20: -500 | M20: 부분개선 | N20: 1387.55 | O20: 2565.36 | P20: 84.88 | Q20: 1713.74 | R20: 23.51 | S20: -430 | T20: -420 | U20: 개선 | V20: 한 연도 개선, 한 연도 부분개선
A21: 낙동강 | B21: 남강 | C21: 함양군(안의교) | D21: 불가 | E21: 수위-유량 곡선 | F21: 45.44 | G21: 296.12 | H21: 551.67 | I21: 296.12 | J21: 551.67 | K21: 11690 | L21: 11690 | M21: 변화없음 | N21: 0.00 | O21: 235.53 | Q21: 235.53 | S21: 22400 | T21: 22400 | U21: 불가 | V21: 2023년: 변화없음, 2024년: 불가
A22: 낙동강 | B22: 내성천 | C22: 봉화군(봉화대교) | D22: 불가 | E22: 수위-유량 곡선 | F22: 851.51 | G22: 548.63 | H22: -35.57 | I22: 525.66 | J22: -38.27 | K22: -70 | L22: -70 | M22: 불가 | N22: 60.08 | O22: 123.00 | P22: 104.73 | Q22: 113.75 | R22: 89.33 | S22: -30 | T22: -20 | U22: 개선 | V22: 2023년: 불가, 2024년: 개선
A23: 낙동강 | B23: 내성천 | C23: 예천군(회룡교) | D23: 개선 | F23: 3016.21 | G23: 3598.49 | H23: 19.31 | I23: 3015.01 | J23: -0.04 | K23: -210 | L23: -190 | M23: 개선 | N23: 388.09 | O23: 708.05 | P23: 82.44 | Q23: 499.52 | R23: 28.71 | S23: -840 | T23: -560 | U23: 개선 | V23: 2023, 2024 모두 개선
A24: 낙동강 | B24: 단장천 | C24: 밀양시(금곡리) | D24: 개선 | F24: 255.34 | G24: 535.41 | H24: 109.69 | I24: 214.44 | J24: -16.02 | K24: -2680 | L24: -60 | M24: 개선 | N24: 200.12 | O24: 490.55 | P24: 145.13 | Q24: 215.48 | R24: 7.68 | S24: -150 | T24: -30 | U24: 개선 | V24: 2023, 2024 모두 개선
A25: 낙동강 | B25: 동창천 | C25: 청도군(매전교) | D25: 불가 | E25: 수위-유량 곡선 | F25: 1309.23 | G25: 134.90 | H25: -89.70 | I25: 165.30 | J25: -87.37 | K25: -160 | L25: -170 | M25: 부분개선 | N25: 1212.63 | O25: 106.27 | P25: -91.24 | Q25: 117.72 | R25: -90.29 | S25: -160 | T25: -140 | U25: 개선 | V25: 한 연도 개선, 한 연도 부분개선
A26: 낙동강 | B26: 미천 | C26: 안동시(운산리) | D26: 부분개선 | F26: 654.42 | G26: 283.00 | H26: -56.76 | I26: 175.58 | J26: -73.17 | K26: -20 | L26: 80 | M26: 불가 | N26: 209.48 | O26: 320.85 | P26: 53.16 | Q26: 235.29 | R26: 12.32 | S26: 40 | T26: 80 | U26: 부분개선 | V26: 2023년: 불가, 2024년: 부분개선
A27: 낙동강 | B27: 밀양강 | C27: 밀양시(용평동) | D27: 개선 | F27: 1202.80 | G27: 1386.87 | H27: 15.30 | I27: 937.54 | J27: -22.05 | K27: 140 | L27: 0 | M27: 부분개선 | N27: 535.41 | O27: 1050.99 | P27: 96.30 | Q27: 608.34 | R27: 13.62 | S27: -130 | T27: -50 | U27: 개선 | V27: 한 연도 개선, 한 연도 부분개선
A28: 낙동강 | B28: 반변천 | C28: 영양군(청암교) | D28: 개선 | F28: 920.75 | G28: 1226.01 | H28: 33.15 | I28: 962.49 | J28: 4.53 | K28: -30 | L28: 80 | M28: 부분개선 | N28: 278.72 | O28: 348.12 | P28: 24.90 | Q28: 294.48 | R28: 5.65 | S28: -150 | T28: -30 | U28: 개선 | V28: 한 연도 개선, 한 연도 부분개선
A29: 낙동강 | B29: 병성천 | C29: 상주시(화계교) | D29: 부분개선 | F29: 207.23 | G29: 166.95 | H29: -19.44 | I29: 146.44 | J29: -29.33 | K29: 50 | L29: 60 | M29: 불가 | N29: 144.94 | O29: 176.52 | P29: 21.79 | Q29: 159.09 | R29: 9.76 | S29: 130 | T29: 130 | U29: 부분개선 | V29: 2023년: 불가, 2024년: 부분개선
A30: 낙동강 | B30: 북천 | C30: 상주시(후천교) | D30: 개선 | F30: 350.67 | G30: 228.44 | H30: -34.86 | I30: 239.01 | J30: -31.84 | K30: 150 | L30: -50 | M30: 개선 | N30: 167.93 | O30: 149.99 | P30: -10.68 | Q30: 162.39 | R30: -3.30 | S30: -10 | T30: -10 | U30: 부분개선 | V30: 한 연도 개선, 한 연도 부분개선
A31: 낙동강 | B31: 서천 | C31: 영주시(월호교) | D31: 개선 | F31: 1201.89 | G31: 1393.41 | H31: 15.93 | I31: 1384.93 | J31: 15.23 | K31: -10 | L31: 0 | M31: 개선 | N31: 327.89 | O31: 290.88 | P31: -11.29 | Q31: 290.55 | R31: -11.39 | S31: -80 | T31: -70 | U31: 부분개선 | V31: 한 연도 개선, 한 연도 부분개선
A32: 낙동강 | B32: 신천 | C32: 대구시(성북교) | D32: 불가 | E32: 이상치/결측치 | F32: 349.28 | G32: 542.10 | H32: 55.20 | I32: 542.10 | J32: 55.20 | K32: -100 | L32: -100 | M32: 변화없음 | N32: 181.13 | O32: 208.95 | P32: 15.36 | Q32: 208.95 | R32: 15.36 | S32: 16380 | T32: 16380 | U32: 변화없음 | V32: 2023, 2024 모두 변화없음 (매개변수 조정 불필요)
A33: 낙동강 | B33: 쌍계천 | C33: 의성군(덕은교) | D33: 개선 | F33: 489.46 | G33: 319.63 | H33: -34.70 | I33: 431.81 | J33: -11.78 | K33: -40 | L33: -50 | M33: 부분개선 | N33: 459.97 | O33: 233.58 | P33: -49.22 | Q33: 382.30 | R33: -16.89 | S33: 260 | T33: -70 | U33: 개선 | V33: 한 연도 개선, 한 연도 부분개선
A34: 낙동강 | B34: 안림천 | C34: 고령군(귀원교) | D34: 개선 | F34: 815.22 | G34: 915.66 | H34: 12.32 | I34: 722.89 | J34: -11.33 | K34: -20 | L34: -10 | M34: 개선 | N34: 111.04 | O34: 161.50 | P34: 45.44 | Q34: 137.84 | R34: 24.14 | S34: -180 | T34: -180 | U34: 부분개선 | V34: 한 연도 개선, 한 연도 부분개선
A35: 낙동강 | B35: 양산천 | C35: 양산시(양산교) | D35: 개선 | F35: 341.66 | G35: 688.93 | H35: 101.64 | I35: 584.08 | J35: 70.95 | K35: -230 | L35: -220 | M35: 개선 | N35: 642.99 | O35: 723.83 | P35: 12.57 | Q35: 676.53 | R35: 5.22 | S35: -60 | T35: -20 | U35: 개선 | V35: 2023, 2024 모두 개선
A36: 낙동강 | B36: 영강 | C36: 문경시(김용리) | D36: 개선 | F36: 2349.37 | G36: 2378.18 | H36: 1.23 | I36: 2386.92 | J36: 1.60 | K36: -40 | L36: -40 | M36: 불가 | N36: 632.82 | O36: 626.06 | P36: -1.07 | Q36: 630.59 | R36: -0.35 | S36: -260 | T36: -250 | U36: 개선 | V36: 2023년: 불가, 2024년: 개선
A37: 낙동강 | B37: 영천강 | C37: 진주시(옥산교) | D37: 개선 | F37: 506.66 | G37: 390.44 | H37: -22.94 | I37: 570.49 | J37: 12.60 | K37: -30 | L37: -40 | M37: 부분개선 | N37: 1032.16 | O37: 735.76 | P37: -28.72 | Q37: 927.94 | R37: -10.10 | S37: -30 | T37: -40 | U37: 부분개선 | V37: 2023, 2024 모두 부분개선
A38: 낙동강 | B38: 오목천 | C38: 경산시(압량교) | D38: 개선 | F38: 253.49 | G38: 147.57 | H38: -41.78 | I38: 147.65 | J38: -41.75 | K38: -40 | L38: 0 | M38: 개선 | N38: 89.89 | O38: 89.71 | P38: -0.20 | Q38: 89.75 | R38: -0.16 | S38: -50 | T38: -20 | U38: 개선 | V38: 2023, 2024 모두 개선
A39: 낙동강 | B39: 위천 | C39: 군위군(무성리) | D39: 변화없음 | F39: 696.22 | G39: 768.04 | H39: 10.32 | I39: 768.04 | J39: 10.32 | K39: -30 | L39: -30 | M39: 변화없음 | N39: 517.78 | O39: 484.57 | P39: -6.41 | Q39: 484.57 | R39: -6.41 | S39: 280 | T39: 280 | U39: 변화없음 | V39: 2023, 2024 모두 변화없음 (매개변수 조정 불필요)
A40: 낙동강 | B40: 위천 | C40: 의성군(장송교) | D40: 개선 | F40: 1586.45 | G40: 1847.53 | H40: 16.46 | I40: 1677.00 | J40: 5.71 | K40: -250 | L40: -240 | M40: 개선 | N40: 950.70 | O40: 1167.86 | P40: 22.84 | Q40: 1019.49 | R40: 7.24 | S40: -180 | T40: -170 | U40: 개선 | V40: 2023, 2024 모두 개선
...

Sheet Sheet1
B2: Basin | C2: River | D2: Station | E2: 2023 | I2: 2024 | M2: Classification | N2: Note
E3: Peak error (%) | G3: Time error (min) | I3: Peak error (%) | K3: Time error (min)
E4: Before | F4: After | G4: Before | H4: After | I4: Before | J4: After | K4: Before | L4: After
B5: Nakdong | C5: Gamcheon | D5: Gimcheon-si (Gimcheon Bridge) | E5: 5.49 | F5: -39.19 | G5: -90 | H5: -60 | I5: 121.78 | J5: 9.24 | K5: -220 | L5: -160 | M5: Partially improved
B6: Nakdong | C6: Geumcheon | D6: Yecheon-gun (Sanyang Bridge) | E6: 54.87 | F6: 53.23 | G6: -140 | H6: -110 | I6: -3.86 | J6: -4.15 | K6: -70 | L6: -30 | M6: Improved
B7: Nakdong | C7: Geumho River | D7: Daegu (Sinam-dong) | E7: -10.24 | F7: -25.57 | G7: -280 | H7: -280 | I7: 441.26 | J7: 295.51 | K7: 210 | L7: 270 | M7: Not applicable | N7: Outlier/Missing data
B8: Nakdong | C8: Geumho River | D8: Yeongcheon-si (Geumchang Bridge) | E8: -22.06 | F8: -30.23 | G8: -40 | H8: -50 | I8: -2.13 | J8: -6.64 | K8: -580 | L8: -590 | M8: Not applicable | N8: Rating curve
B9: Nakdong | C9: Geumho River | D9: Yeongcheon-si (Yeongdong Bridge) | E9: -30.63 | F9: -43.63 | G9: 120 | H9: -50 | I9: 939.48 | J9: 395.84 | K9: 14570 | L9: 14140 | M9: Not applicable | N9: Weir operation
B10: Nakdong | C10: Gilan Stream | D10: Andong-si (Mukgye Bridge) | E10: 45.02 | F10: 0.3 | G10: -170 | H10: 60 | I10: 38.11 | J10: 3.5 | K10: -80 | L10: -40 | M10: Improved
B11: Nakdong | C11: Nakdong River | D11: Daegu (Seonghari) | E11: 33.51 | F11: 20.47 | G11: 3910 | H11: 3960 | I11: 106.5 | J11: 84.37 | K11: -1120 | L11: -1110 | M11: Not applicable | N11: Main stem (weir operation)
B12: Nakdong | C12: Nakdong River | D12: Miryang-si (Samrangjin Bridge) | E12: 125.44 | F12: 94.19 | G12: 2350 | H12: 2340 | I12: 133.43 | J12: 99.57 | K12: -1100 | L12: -1090 | M12: Not applicable | N12: Main stem (weir operation)
B13: Nakdong | C13: Nakdong River | D13: Bonghwa-gun (Buncheon Bridge) | E13: 61.77 | F13: 17.34 | G13: -320 | H13: -290 | I13: 65.71 | J13: 2.08 | K13: -250 | L13: -210 | M13: Improved
B14: Nakdong | C14: Nakdong River | D14: Busan (Gupo Bridge) | E14: 138.73 | F14: 106.78 | G14: 2780 | H14: 2770 | I14: 117.34 | J14: 89.32 | K14: -940 | L14: -930 | M14: Not applicable | N14: Tidal influence
B15: Nakdong | C15: Nakdong River | D15: Yecheon-gun (Gudam Bridge) | E15: -13.02 | F15: -21.84 | G15: 3560 | H15: 3580 | I15: 6.27 | J15: -8.41 | K15: -740 | L15: -680 | M15: Not applicable | N15: Rating curve
B16: Nakdong | C16: Nakdong River | D16: Yecheon-gun (Sangpung Bridge) | E16: 11.8 | F16: 3.02 | G16: -280 | H16: -270 | I16: 61.92 | J16: 37.97 | K16: -920 | L16: -870 | M16: Not applicable | N16: Dam operation
B17: Nakdong | C17: Nakdong River | D17: Uiseong-gun (Nakdan Bridge) | E17: 22.68 | F17: 13.54 | G17: -480 | H17: -460 | I17: 55.64 | J17: 36.7 | K17: -1060 | L17: -1040 | M17: Not applicable | N17: Main stem (weir operation)
B18: Nakdong | C18: Nakdong River | D18: Chilgok-gun (Hogukui Bridge) | E18: 21.17 | F18: 12.41 | G18: -920 | H18: -910 | I18: 138.59 | J18: 112.28 | K18: -260 | L18: -240 | M18: Not applicable | N18: Main stem (weir operation)
B19: Nakdong | C19: Nakdong River | D19: Haman-gun (Gyennaeri) | E19: 135.11 | F19: 102.97 | G19: 3200 | H19: 3220 | I19: 121.14 | J19: 87.29 | K19: -1260 | L19: -1250 | M19: Not applicable | N19: Main stem (weir operation)
B20: Nakdong | C20: Nakdong River | D20: Hapcheon-gun (Jeokpo Bridge) | E20: 81.93 | F20: 56.72 | G20: 3610 | H20: 3620 | I20: 89.48 | J20: 66.86 | K20: -1280 | L20: -1270 | M20: Not applicable | N20: Main stem (weir operation)
B21: Nakdong | C21: Nam River | D21: Sancheong-gun (Gyeongho Bridge) | E21: -13.17 | F21: -15.82 | G21: -150 | H21: -130 | I21: 5.19 | J21: 5.81 | K21: -400 | L21: -400 | M21: Not applicable | N21: Rating curve
B22: Nakdong | C22: Nam River | D22: Uiryeong-gun (Jeongam Bridge) | E22: 42.67 | F22: 5.31 | G22: -500 | H22: -500 | I22: 84.88 | J22: 23.51 | K22: -430 | L22: -420 | M22: Improved
B23: Nakdong | C23: Nam River | D23: Hamyang-gun (Anui Bridge) | E23: 551.67 | F23: 551.67 | G23: 11690 | H23: 11690 | K23: 22400 | L23: 22400 | M23: Not applicable | N23: Rating curve
B24: Nakdong | C24: Naeseong Stream | D24: Bonghwa-gun (Bonghwa Bridge) | E24: -35.57 | F24: -38.27 | G24: -70 | H24: -70 | I24: 104.73 | J24: 89.33 | K24: -30 | L24: -20 | M24: Not applicable | N24: Rating curve
B25: Nakdong | C25: Naeseong Stream | D25: Yecheon-gun (Hoeryong Bridge) | E25: 19.31 | F25: -0.04 | G25: -210 | H25: -190 | I25: 82.44 | J25: 28.71 | K25: -840 | L25: -560 | M25: Improved
B26: Nakdong | C26: Danjang Stream | D26: Miryang-si (Geumgok-ri) | E26: 109.69 | F26: -16.02 | G26: -2680 | H26: -60 | I26: 145.13 | J26: 7.68 | K26: -150 | L26: -30 | M26: Improved
B27: Nakdong | C27: Dongchang Stream | D27: Cheongdo-gun (Maejeon Bridge) | E27: -89.7 | F27: -87.37 | G27: -160 | H27: -170 | I27: -91.24 | J27: -90.29 | K27: -160 | L27: -140 | M27: Not applicable | N27: Rating curve
B28: Nakdong | C28: Micheon Stream | D28: Andong-si (Unsan-ri) | E28: -56.76 | F28: -73.17 | G28: -20 | H28: 80 | I28: 53.16 | J28: 12.32 | K28: 40 | L28: 80 | M28: Partially improved
B29: Nakdong | C29: Miryang River | D29: Miryang-si (Yongpyeong-dong) | E29: 15.3 | F29: -22.05 | G29: 140 | H29: 0 | I29: 96.3 | J29: 13.62 | K29: -130 | L29: -50 | M29: Improved
B30: Nakdong | C30: Banbyeon Stream | D30: Yeongyang-gun (Cheongam Bridge) | E30: 33.15 | F30: 4.53 | G30: -30 | H30: 80 | I30: 24.9 | J30: 5.65 | K30: -150 | L30: -30 | M30: Improved
B31: Nakdong | C31: Byeongseong Stream | D31: Sangju-si (Hwagye Bridge) | E31: -19.44 | F31: -29.33 | G31: 50 | H31: 60 | I31: 21.79 | J31: 9.76 | K31: 130 | L31: 130 | M31: Partially improved
B32: Nakdong | C32: Buk Stream | D32: Sangju-si (Hucheon Bridge) | E32: -34.86 | F32: -31.84 | G32: 150 | H32: -50 | I32: -10.68 | J32: -3.3 | K32: -10 | L32: -10 | M32: Improved
B33: Nakdong | C33: Seo Stream | D33: Yeongju-si (Wolho Bridge) | E33: 15.93 | F33: 15.23 | G33: -10 | H33: 0 | I33: -11.29 | J33: -11.39 | K33: -80 | L33: -70 | M33: Improved
B34: Nakdong | C34: Sincheon Stream | D34: Daegu (Seongbuk Bridge) | E34: 55.2 | F34: 55.2 | G34: -100 | H34: -100 | I34: 15.36 | J34: 15.36 | K34: 16380 | L34: 16380 | M34: Not applicable | N34: Outlier/Missing data
B35: Nakdong | C35: Ssanggye Stream | D35: Uiseong-gun (Deogeun Bridge) | E35: -34.7 | F35: -11.78 | G35: -40 | H35: -50 | I35: -49.22 | J35: -16.89 | K35: 260 | L35: -70 | M35: Improved
B36: Nakdong | C36: Anrim Stream | D36: Goryeong-gun (Gwiwon Bridge) | E36: 12.32 | F36: -11.33 | G36: -20 | H36: -10 | I36: 45.44 | J36: 24.14 | K36: -180 | L36: -180 | M36: Improved
B37: Nakdong | C37: Yangsan Stream | D37: Yangsan-si (Yangsan Bridge) | E37: 101.64 | F37: 70.95 | G37: -230 | H37: -220 | I37: 12.57 | J37: 5.22 | K37: -60 | L37: -20 | M37: Improved
B38: Nakdong | C38: Yeong Stream | D38: Mungyeong-si (Gimyong-ri) | E38: 1.23 | F38: 1.6 | G38: -40 | H38: -40 | I38: -1.07 | J38: -0.35 | K38: -260 | L38: -250 | M38: Improved
B39: Nakdong | C39: Yeongcheon River | D39: Jinju-si (Oksan Bridge) | E39: -22.94 | F39: 12.6 | G39: -30 | H39: -40 | I39: -28.72 | J39: -10.1 | K39: -30 | L39: -40 | M39: Improved
B40: Nakdong | C40: Omok Stream | D40: Gyeongsan-si (Apryang Bridge) | E40: -41.78 | F40: -41.75 | G40: -40 | H40: 0 | I40: -0.2 | J40: -0.16 | K40: -50 | L40: -20 | M40: Improved
B41: Nakdong | C41: Wicheon Stream | D41: Gunwi-gun (Museong-ri) | E41: 10.32 | F41: 10.32 | G41: -30 | H41: -30 | I41: -6.41 | J41: -6.41 | K41: 280 | L41: 280 | M41: Unchanged
...

Sheet Sheet3
B2: Year | C2: Metric | D2: Before calibration | E2: After calibration
B3: 2023 | C3: Median peak-flow error (%) | D3: 28.41 | E3: 25.22
B4: 2023 | C4: Median time-to-peak error (min) | D4: 140 | E4: 80
B5: 2024 | C5: Median peak-flow error (%) | D5: 38.9 | E5: 9.76
B6: 2024 | C6: Median time-to-peak error (min) | D6: 205 | E6: 155
